Workbook

Sheet 工时评估汇总表 
B1: 类型 | C1: 模块 | D1: 一级功能 | E1: 功能点开发数 | Q1: 总工时 | R1: 费用(元) | S1: 小计 (万元) | T1: 总预算(元)
E2: 画面 | F2: 报表 | G2: 批处理 | H2: 接口 | I2: 流程 | J2: 导入 | K2: 导出 | L2: 难度系数
L3: 极高 | M3: 高 | N3: 中 | O3: 低 | P3: 极低
B4: 大圣外采 | C4: =工时评估明细表!B3 -> GRT销售 | D4: =工时评估明细表!C3 -> 功能1 | E4: =SUMIF(工时评估明细表!$G$3:$G$16,E2,工时评估明细表!$H$3:$H$16) -> 3 | F4: =SUMIF(工时评估明细表!$G$3:$G$16,F2,工时评估明细表!$H$3:$H$16) -> 5 | G4: =SUMIF(工时评估明细表!$G$3:$G$16,G2,工时评估明细表!$H$3:$H$16) -> 3 | H4: =SUMIF(工时评估明细表!$G$3:$G$16,H2,工时评估明细表!$H$3:$H$16) -> 5 | I4: =SUMIF(工时评估明细表!$G$3:$G$16,I2,工时评估明细表!$H$3:$H$16) -> 2 | J4: =SUMIF(工时评估明细表!$G$3:$G$16,J2,工时评估明细表!$H$3:$H$16) -> 3 | K4: =SUMIF(工时评估明细表!$G$3:$G$16,K2,工时评估明细表!$H$3:$H$16) -> 2 | L4: =SUMIF(工时评估明细表!$I$3:$I$16,L3,工时评估明细表!$H$3:$H$16)/SUM(工时评估明细表!$H$3:$H$16) -> 0.13043478 | M4: =SUMIF(工时评估明细表!$I$3:$I$16,M3,工时评估明细表!$H$3:$H$16)/SUM(工时评估明细表!$H$3:$H$16) -> 0.39130435 | N4: =SUMIF(工时评估明细表!$I$3:$I$16,N3,工时评估明细表!$H$3:$H$16)/SUM(工时评估明细表!$H$3:$H$16) -> 0.26086957 | O4: =SUMIF(工时评估明细表!$I$3:$I$16,O3,工时评估明细表!$H$3:$H$16)/SUM(工时评估明细表!$H$3:$H$16) -> 0.086956522 | P4: =SUMIF(工时评估明细表!$I$3:$I$16,P3,工时评估明细表!$H$3:$H$16)/SUM(工时评估明细表!$H$3:$H$16) -> 0.13043478 | Q4: =工时评估明细表!K3 -> 98.6 | R4: =SUM(Q4:Q6) -> 98.6 | S4: =SUM(R4:R7) -> 198.6
D7: 云资源 | R7: 100
B8: 大圣自研
B20: *注意：需要预留云资源

Sheet 工时评估明细表
A1: 序号 | B1: 模块 | C1: 一级功能 | D1: 二级功能 | E1: 描述 | F1: 区分 | G1: 分类 | H1: 数量 | I1: 难度 | J1: 工时 | K1: 小计 | L1: 备注
C2: 功能模块 | D2: 功能点 | E2: 描述 | F2: 类别 | G2: 分类 | H2: 数量 | I2: 难度
A3: 1 | B3: GRT销售 | C3: 功能1 | D3: 子功能1 | E3: 功能描述 | F3: 新增 | G3: 画面 | H3: 2 | I3: 高 | J3: =IFERROR(VLOOKUP(F3&G3&I3,Sheet1!$A$1:$B$70,2,0)*$H3,"") -> 6 | K3: =SUM(J3:J16) -> 98.6
A4: 2 | F4: 新增 | G4: 报表 | H4: 2 | I4: 极低 | J4: =IFERROR(VLOOKUP(F4&G4&I4,Sheet1!$A$1:$B$70,2,0)*$H4,"") -> 5
A5: 3 | F5: 新增 | G5: 批处理 | H5: 1 | I5: 中 | J5: =IFERROR(VLOOKUP(F5&G5&I5,Sheet1!$A$1:$B$70,2,0)*$H5,"") -> 4
F6: 新增 | G6: 接口 | H6: 1 | I6: 低 | J6: =IFERROR(VLOOKUP(F6&G6&I6,Sheet1!$A$1:$B$70,2,0)*$H6,"") -> 4
A7: 4 | F7: 新增 | G7: 流程 | H7: 1 | I7: 高 | J7: =IFERROR(VLOOKUP(F7&G7&I7,Sheet1!$A$1:$B$70,2,0)*$H7,"") -> 9
A8: 5 | F8: 新增 | G8: 导入 | H8: 2 | I8: 高 | J8: =IFERROR(VLOOKUP(F8&G8&I8,Sheet1!$A$1:$B$70,2,0)*$H8,"") -> 12
A9: 6 | F9: 新增 | G9: 导出 | H9: 1 | I9: 极高 | J9: =IFERROR(VLOOKUP(F9&G9&I9,Sheet1!$A$1:$B$70,2,0)*$H9,"") -> 6
A10: 7 | D10: 子功能2 | E10: 功能描述 | F10: 修改 | G10: 画面 | H10: 1 | I10: 中 | J10: =IFERROR(VLOOKUP(F10&G10&I10,Sheet1!$A$1:$B$70,2,0)*$H10,"") -> 1
A11: 8 | F11: 修改 | G11: 报表 | H11: 3 | I11: 高 | J11: =IFERROR(VLOOKUP(F11&G11&I11,Sheet1!$A$1:$B$70,2,0)*$H11,"") -> 13.5
A12: 9 | F12: 修改 | G12: 批处理 | H12: 2 | I12: 极高 | J12: =IFERROR(VLOOKUP(F12&G12&I12,Sheet1!$A$1:$B$70,2,0)*$H12,"") -> 12
A13: 10 | F13: 修改 | G13: 接口 | H13: 4 | I13: 中 | J13: =IFERROR(VLOOKUP(F13&G13&I13,Sheet1!$A$1:$B$70,2,0)*$H13,"") -> 16
F14: 修改 | G14: 流程 | H14: 1 | I14: 高 | J14: =IFERROR(VLOOKUP(F14&G14&I14,Sheet1!$A$1:$B$70,2,0)*$H14,"") -> 7.5
A15: 11 | F15: 修改 | G15: 导入 | H15: 1 | I15: 低 | J15: =IFERROR(VLOOKUP(F15&G15&I15,Sheet1!$A$1:$B$70,2,0)*$H15,"") -> 1.6
A16: 12 | F16: 修改 | G16: 导出 | H16: 1 | I16: 极低 | J16: =IFERROR(VLOOKUP(F16&G16&I16,Sheet1!$A$1:$B$70,2,0)*$H16,"") -> 1
A17: 13 | J17: =IFERROR(VLOOKUP(F17&G17&I17,[1]Sheet1!F17:G76,2,0)*$H17,"")
A18: 14 | J18: =IFERROR(VLOOKUP(F18&G18&I18,[1]Sheet1!F18:G77,2,0)*$H18,"")
A19: 15 | J19: =IFERROR(VLOOKUP(F19&G19&I19,[1]Sheet1!F19:G78,2,0)*$H19,"")
A20: 16 | J20: =IFERROR(VLOOKUP(F20&G20&I20,[1]Sheet1!F20:G79,2,0)*$H20,"")
A21: 17 | J21: =IFERROR(VLOOKUP(F21&G21&I21,[1]Sheet1!F21:G80,2,0)*$H21,"")
A22: 18 | J22: =IFERROR(VLOOKUP(F22&G22&I22,[1]Sheet1!F22:G81,2,0)*$H22,"")
A23: 19 | J23: =IFERROR(VLOOKUP(F23&G23&I23,[1]Sheet1!F23:G82,2,0)*$H23,"")
A24: 20 | J24: =IFERROR(VLOOKUP(F24&G24&I24,[1]Sheet1!F24:G83,2,0)*$H24,"")

Sheet 工时标准
A1: 功能标准人天定义
A2: 分类 | B2: 标准工时（人天）
B3: 新增 | C3: 修改
A4: 画面 | B4: 2 | C4: 1
A5: 报表 | B5: 5 | C5: 3
A6: 批处理 | B6: 4 | C6: 3
A7: 接口 | B7: 5 | C7: 4
A8: 流程 | B8: 6 | C8: 5
A9: 导入 | B9: 4 | C9: 2
A10: 导出 | B10: 3 | C10: 2
A12: 难度定义
A13: 分类 | B13: 等级 | C13: 系数 | D13: 等级定义
A14: 画面 | B14: 极高 | C14: 2 | D14: 安卓、IOS、小程序、PC端、H5兼容
B15: 高 | C15: 1.5 | D15: 用户交互逻辑，包括画面拖拽，拣选，
B16: 中 | C16: 1 | D16: 页面布局调整
B17: 低 | C17: 0.8 | D17: 纯数据输入与展示
B18: 极低 | C18: 0.5 | D18: 1、纯文案类型，单纯对文案进行调整 2、图片/图标替换。
A19: 报表 | B19: 极高 | C19: 2 | D19: 多表分析，系统处理逻辑复杂，特殊图表（如动态图表）展示
B20: 高 | C20: 1.5 | D20: 多表分析，涉及自定义的逻辑分析处理
B21: 中 | C21: 1 | D21: 多表分析，包含一定的复杂度逻辑分析处理
B22: 低 | C22: 0.8 | D22: 涉及多表的联查，包含简单的汇总分组等逻辑处理
B23: 极低 | C23: 0.5 | D23: 单表信息的展示，包含简单的汇总分组等逻辑处理
A24: 批处理 | B24: 极高 | C24: 2 | D24: 在X>=5 张表数据处理， 复杂逻辑
B25: 高 | C25: 1.5 | D25: 在2<X<5 张表数据处理， 复杂逻辑
B26: 中 | C26: 1 | D26: 在2<X<5 张表数据处理， 简答逻辑，数据量>10w
B27: 低 | C27: 0.8 | D27: 在2<X<5 张表数据处理， 简单逻辑，数据量<10w
B28: 极低 | C28: 0.5 | D28: 单表数据处理，简单逻辑，数据量<10w
A29: 接口 | B29: 极高 | C29: 2 | D29: 表数量>=3复杂的业务逻辑、高复杂的业务规则
B30: 高 | C30: 1.5 | D30: 表数量>=3复杂的业务逻辑、较复杂的业务规则
B31: 中 | C31: 1 | D31: 表数量<3的数据对象的交互，处理简单业务规则
B32: 低 | C32: 0.8 | D32: 简单的数据传输，单表数据增删改查的逻辑处理
B33: 极低 | C33: 0.5 | D33: 只是对接口名称、参数名称||类型||长度等简单调整
A34: 流程 | B34: 极高 | C34: 2 | D34: 有分支流程，并含有迭代、循环等流程，涉及参与节点三个以上
B35: 高 | C35: 1.5 | D35: 有分支流程，涉及参与节点三个以上
B36: 中 | C36: 1 | D36: 有分支流程，涉及参与节点三个以下
B37: 低 | C37: 0.8 | D37: 线性流程，涉及参与节点三个以上
B38: 极低 | C38: 0.5 | D38: 线性流程，涉及参与节点三个以下
A39: 导入 | B39: 极高 | C39: 2 | D39: 特殊格式的文件导入
B40: 高 | C40: 1.5 | D40: 数据量>=10w；进行复杂校验，包括业务逻辑处理
B41: 中 | C41: 1 | D41: 数据量>=1w；进行稍微复杂校验，包括异常值处理与与处理结果显示
...

Sheet Sheet1
A1: 新增画面极高 | B1: 4
A2: 新增画面高 | B2: 3
A3: 新增画面中 | B3: 2
A4: 新增画面低 | B4: 1.6
A5: 新增画面极低 | B5: 1
A6: 新增报表极高 | B6: 10
A7: 新增报表高 | B7: 7.5
A8: 新增报表中 | B8: 5
A9: 新增报表低 | B9: 4
A10: 新增报表极低 | B10: 2.5
A11: 新增批处理极高 | B11: 8
A12: 新增批处理高 | B12: 6
... A70: 修改导出极低 | B70: 1
